<?xml version="1.0"?>
<robot xmlns:xacro="http://www.ros.org/wiki/xacro">
    <xacro:include filename="$(find robot_description)/urdf/NaviRobot/common_inertia.xacro"/>
    <!-- ========== 主动轮 ========== -->
    <xacro:macro name="wheel_xacro" params="wheel_name xyz">
        <link name="${wheel_name}_link">
            <visual>
                <origin xyz="0 0 0" rpy="1.57079 0 0"/>
                <geometry>
                    <cylinder length="0.04" radius="0.032"/>
                </geometry>
                <material name="blue">
                    <color rgba="0.0 0.0 1.0 0.8"/>
                </material>
            </visual>
            <!-- 碰撞特性 -->
            <collision> 
                <origin xyz="0 0 0" rpy="1.57079 0 0"/>
                <geometry>
                    <cylinder length="0.04" radius="0.032"/>
                </geometry>
                <material name="blue">
                    <color rgba="0.0 0.0 1.0 0.8"/>
                </material>
            </collision>
            <xacro:cylinder_inertia m="0.1" h="0.04" r="0.032"/>
        </link>

        <!-- ========== 固定主动轮到机器人底部 ========== -->
        <joint name="${wheel_name}_joint" type="continuous">
            <parent link="base_link"/>
            <child link="${wheel_name}_link"/>
            <origin xyz="${xyz}" rpy="0.0 0.0 0.0"/>
            <axis xyz="0.0 1.0 0.0"/>
        </joint>

        <gazebo reference="${wheel_name}_wheel_link">
            <material>Gazebo/Black</material>
            <mu1 value="50.0" />
            <mu2 value="50.0" />
            <kp value="1000000.0" />
            <kd value="10.0" />
        </gazebo>
    </xacro:macro>

</robot>